Workbook

Sheet Dash Board
A4: Sales Order Approval Request-Single Lot | C4: Error Check
A5: Sales Order No | B5: =IFERROR(('Sales Order'!J8),"") -> 0 | C5: =IF(B5=0,"Error Pls Fill in the Details","Ok") -> Error Pls Fill in the Details
A6: Sales Person: | B6: =IFERROR(('Sales Order'!F6),"") -> 0 | C6: =IF(B6=0,"Error Pls Fill in the Details","Ok") -> Error Pls Fill in the Details
A7: Client / Site / Project name: | B7: =IFERROR(('Sales Order'!K21),"") -> 0 | C7: =IF(B7=0,"Error Pls Fill in the Details","Ok") -> Error Pls Fill in the Details
A8: Business Segment: | B8: =IFERROR(('Sales Order'!C7),"") -> Housing-Residential Project - HR | C8: =IF(B8=0,"Error Pls Fill in the Details","Ok") -> Ok
A9: Distributor Name: | B9: =IFERROR(('Sales Order'!C11),"") -> 0 | C9: =IF(B9=0,"Error Pls Fill in the Details","Ok") -> Error Pls Fill in the Details
A10: Distributor Location: | B10: =IFERROR(('Sales Order'!C14),"") -> 0 | C10: =IF(B10=0,"Error Pls Fill in the Details","Ok") -> Error Pls Fill in the Details
A11: Bitrix ID: | B11: =IFERROR(('Sales Order'!C9),"") -> 0 | C11: =IF(B11=0,"Error Pls Fill in the Details","Ok") -> Error Pls Fill in the Details
A12: Order Basic Value ₹: | B12: =IFERROR(('Sales Order'!N100),"") -> 0 | C12: =IF(B12=0,"Error Pls Fill in the Details","Ok") -> Error Pls Fill in the Details
A13: Cash Discount | B13: =IFERROR(('Sales Order'!C17),"") -> 0.03 | C13: =IF(B13=0,"Error Pls Fill in the Details","Ok") -> Ok
A14: Average Discount on MRP: | B14: =IFERROR((AVERAGE('Sales Order'!L25:L99)),"") -> 0.5344 | C14: =IF(B14=0,"Error Pls Fill in the Details","Ok") -> Ok
A15: Freight Condition | B15: =IFERROR(('Sales Order'!C18),"") -> FOR | C15: =IF(B15=0,"Error Pls Fill in the Details","Ok") -> Ok
A16: Payment Terms | B16: =IFERROR(('Sales Order'!C19),"") -> Advance | C16: =IF(B16=0,"Error Pls Fill in the Details","Ok") -> Ok
A17: Rera Project no. | B17: ='Sales Order'!F7 -> 0 | C17: =IF(B17=0,"Error Pls Fill in the Details","Ok") -> Error Pls Fill in the Details
A18: Order Validity: | B18: ='Sales Order'!J7 -> 7 Days | C18: =IF(B18=0,"Error Pls Fill in the Details","Ok") -> Ok
A20: Important Note : RERA number is mandatory. The order value will be displayed as "0" until a valid RERA number for the project is entered. Sales Order will not be processed without this information.

Sheet Sales Order
D1: HULIOT PIPES AND FITTINGS PVT. LTD. | L1: Format No: | N1: HPF-01
L2: Issue Date: | N2: 10.04.2026
D3: 714/715, MANJUSAR GIDC SAVLI | L3: REV. No. | N3: 01
D4: VADODARA, GUJARAT-391770 | L4: REV. Date | N4: =N2 -> 10.04.2026
A5: SALES ORDER FORM
A6: Business Type: | C6: Project | D6: Sales Person: | H6: PO No: | K6: PO Date:
A7: Business Segment: | C7: Housing-Residential Project - HR | D7: Rera Project No: | H7: Order Validity : | J7: 7 Days | K7: Others:
A8: Customer PO No: | D8: Order Basic Value | F8: =N100 -> 0 | H8: Sales Order No: | K8: Date:
A9: Bitrix Deal ID: | D9: Customer Type | F9: Builder | H9: Contact Person Name | K9: Contact Person Mobile
A10: Receiver (Bill to) | H10: Consignee (Ship to)
A11: Name: | H11: Name:
A12: Address : | H12: Address :
A14: City: | H14: City:
A15: Pin Code: | H15: Pin Code:
A16: GSTIN No: | H16: GSTIN No:
A17: Cash Discount: | C17: =IF(C19="Advance ",3%,0%) -> 0.03
A18: Term of Delivery: | C18: FOR
A19: Payment Term: | C19: Advance
A20: Consultant / Architect Firm Name | H20: Consultant / Architect Contact No.
A21: Developer Name / Bungalow Owner Name | H21: Site / Project Name:
A22: Other Remark
A23: S. No | B23: Material No | C23: Description of Goods | D23: DN | E23: Category | F23: MOQ | G23: Order Qty | H23: HSN Code | I23: List Price | J23: Discount | M23: Net Price Per Unit | N23: Basic Order Value ₹ | O23: Product Sub-Group
J24: Discount % | K24: Cash Discount | L24: Net Discount % (After CD)
A25: 1 | B25: 5751100300-i | C25: =IFERROR(VLOOKUP(B25,'Product Master'!$A:$J,2,FALSE),"") -> ULTRA SILENT PIPE WITH ONE SOCKET L 3000 | D25: =IFERROR(VLOOKUP(B25,'Product Master'!$A:$J,3,FALSE),"") -> 110 | E25: =IFERROR(VLOOKUP(B25,'Product Master'!$A:$J,6,FALSE),"") -> US S/S PIPE 3 Mtr | F25: =IFERROR(VLOOKUP(B25,'Product Master'!$A:$J,4,FALSE),"") -> 1 | G25: 10 | H25: =IFERROR(VLOOKUP(B25,'Product Master'!$A:$J,8,FALSE),"") -> 39171020 | I25: =IFERROR(VLOOKUP(B25,'Product Master'!$A:$J,5,FALSE),"") -> 2954 | J25: 0.52 | K25: =IF(ISBLANK($J25),"",$C$17) -> 0.03 | L25: =IFERROR(J25+(100%-J25)*K25,"") -> 0.5344 | M25: =ROUNDUP(IFERROR(I25-(I25*L25),""),2) -> 1375.39 | N25: =IF('Dash Board'!$C$17="Error Pls Fill in the Details",0,IFERROR((G25*M25),"")) -> 0 | O25: =IFERROR(VLOOKUP(B25,'Product Master'!$A:$J,7,FALSE),"") -> US S/S PIPE
A26: 2 | C26: =IFERROR(VLOOKUP(B26,'Product Master'!$A:$J,2,FALSE),"") | D26: =IFERROR(VLOOKUP(B26,'Product Master'!$A:$J,3,FALSE),"") | E26: =IFERROR(VLOOKUP(B26,'Product Master'!$A:$J,6,FALSE),"") | F26: =IFERROR(VLOOKUP(B26,'Product Master'!$A:$J,4,FALSE),"") | H26: =IFERROR(VLOOKUP(B26,'Product Master'!$A:$J,8,FALSE),"") | I26: =IFERROR(VLOOKUP(B26,'Product Master'!$A:$J,5,FALSE),"") | K26: =IF(ISBLANK($J26),"",$C$17) | L26: =IFERROR(J26+(100%-J26)*K26,"") | M26: =ROUNDUP(IFERROR(I26-(I26*L26),""),2) -> #VALUE! | N26: =IF('Dash Board'!$C$17="Error Pls Fill in the Details",0,IFERROR((G26*M26),"")) -> 0 | O26: =IFERROR(VLOOKUP(B26,'Product Master'!$A:$J,7,FALSE),"")
A27: 3 | C27: =IFERROR(VLOOKUP(B27,'Product Master'!$A:$J,2,FALSE),"") | D27: =IFERROR(VLOOKUP(B27,'Product Master'!$A:$J,3,FALSE),"") | E27: =IFERROR(VLOOKUP(B27,'Product Master'!$A:$J,6,FALSE),"") | F27: =IFERROR(VLOOKUP(B27,'Product Master'!$A:$J,4,FALSE),"") | H27: =IFERROR(VLOOKUP(B27,'Product Master'!$A:$J,8,FALSE),"") | I27: =IFERROR(VLOOKUP(B27,'Product Master'!$A:$J,5,FALSE),"") | K27: =IF(ISBLANK($J27),"",$C$17) | L27: =IFERROR(J27+(100%-J27)*K27,"") | M27: =ROUNDUP(IFERROR(I27-(I27*L27),""),2) -> #VALUE! | N27: =IF('Dash Board'!$C$17="Error Pls Fill in the Details",0,IFERROR((G27*M27),"")) -> 0 | O27: =IFERROR(VLOOKUP(B27,'Product Master'!$A:$J,7,FALSE),"")
A28: 4 | C28: =IFERROR(VLOOKUP(B28,'Product Master'!$A:$J,2,FALSE),"") | D28: =IFERROR(VLOOKUP(B28,'Product Master'!$A:$J,3,FALSE),"") | E28: =IFERROR(VLOOKUP(B28,'Product Master'!$A:$J,6,FALSE),"") | F28: =IFERROR(VLOOKUP(B28,'Product Master'!$A:$J,4,FALSE),"") | H28: =IFERROR(VLOOKUP(B28,'Product Master'!$A:$J,8,FALSE),"") | I28: =IFERROR(VLOOKUP(B28,'Product Master'!$A:$J,5,FALSE),"") | K28: =IF(ISBLANK($J28),"",$C$17) | L28: =IFERROR(J28+(100%-J28)*K28,"") | M28: =ROUNDUP(IFERROR(I28-(I28*L28),""),2) -> #VALUE! | N28: =IF('Dash Board'!$C$17="Error Pls Fill in the Details",0,IFERROR((G28*M28),"")) -> 0 | O28: =IFERROR(VLOOKUP(B28,'Product Master'!$A:$J,7,FALSE),"")
A29: 5 | C29: =IFERROR(VLOOKUP(B29,'Product Master'!$A:$J,2,FALSE),"") | D29: =IFERROR(VLOOKUP(B29,'Product Master'!$A:$J,3,FALSE),"") | E29: =IFERROR(VLOOKUP(B29,'Product Master'!$A:$J,6,FALSE),"") | F29: =IFERROR(VLOOKUP(B29,'Product Master'!$A:$J,4,FALSE),"") | H29: =IFERROR(VLOOKUP(B29,'Product Master'!$A:$J,8,FALSE),"") | I29: =IFERROR(VLOOKUP(B29,'Product Master'!$A:$J,5,FALSE),"") | K29: =IF(ISBLANK($J29),"",$C$17) | L29: =IFERROR(J29+(100%-J29)*K29,"") | M29: =ROUNDUP(IFERROR(I29-(I29*L29),""),2) -> #VALUE! | N29: =IF('Dash Board'!$C$17="Error Pls Fill in the Details",0,IFERROR((G29*M29),"")) -> 0 | O29: =IFERROR(VLOOKUP(B29,'Product Master'!$A:$J,7,FALSE),"")
A30: 6 | C30: =IFERROR(VLOOKUP(B30,'Product Master'!$A:$J,2,FALSE),"") | D30: =IFERROR(VLOOKUP(B30,'Product Master'!$A:$J,3,FALSE),"") | E30: =IFERROR(VLOOKUP(B30,'Product Master'!$A:$J,6,FALSE),"") | F30: =IFERROR(VLOOKUP(B30,'Product Master'!$A:$J,4,FALSE),"") | H30: =IFERROR(VLOOKUP(B30,'Product Master'!$A:$J,8,FALSE),"") | I30: =IFERROR(VLOOKUP(B30,'Product Master'!$A:$J,5,FALSE),"") | K30: =IF(ISBLANK($J30),"",$C$17) | L30: =IFERROR(J30+(100%-J30)*K30,"") | M30: =ROUNDUP(IFERROR(I30-(I30*L30),""),2) -> #VALUE! | N30: =IF('Dash Board'!$C$17="Error Pls Fill in the Details",0,IFERROR((G30*M30),"")) -> 0 | O30: =IFERROR(VLOOKUP(B30,'Product Master'!$A:$J,7,FALSE),"")
A31: 7 | C31: =IFERROR(VLOOKUP(B31,'Product Master'!$A:$J,2,FALSE),"") | D31: =IFERROR(VLOOKUP(B31,'Product Master'!$A:$J,3,FALSE),"") | E31: =IFERROR(VLOOKUP(B31,'Product Master'!$A:$J,6,FALSE),"") | F31: =IFERROR(VLOOKUP(B31,'Product Master'!$A:$J,4,FALSE),"") | H31: =IFERROR(VLOOKUP(B31,'Product Master'!$A:$J,8,FALSE),"") | I31: =IFERROR(VLOOKUP(B31,'Product Master'!$A:$J,5,FALSE),"") | K31: =IF(ISBLANK($J31),"",$C$17) | L31: =IFERROR(J31+(100%-J31)*K31,"") | M31: =ROUNDUP(IFERROR(I31-(I31*L31),""),2) -> #VALUE! | N31: =IF('Dash Board'!$C$17="Error Pls Fill in the Details",0,IFERROR((G31*M31),"")) -> 0 | O31: =IFERROR(VLOOKUP(B31,'Product Master'!$A:$J,7,FALSE),"")
A32: 8 | C32: =IFERROR(VLOOKUP(B32,'Product Master'!$A:$J,2,FALSE),"") | D32: =IFERROR(VLOOKUP(B32,'Product Master'!$A:$J,3,FALSE),"") | E32: =IFERROR(VLOOKUP(B32,'Product Master'!$A:$J,6,FALSE),"") | F32: =IFERROR(VLOOKUP(B32,'Product Master'!$A:$J,4,FALSE),"") | H32: =IFERROR(VLOOKUP(B32,'Product Master'!$A:$J,8,FALSE),"") | I32: =IFERROR(VLOOKUP(B32,'Product Master'!$A:$J,5,FALSE),"") | K32: =IF(ISBLANK($J32),"",$C$17) | L32: =IFERROR(J32+(100%-J32)*K32,"") | M32: =ROUNDUP(IFERROR(I32-(I32*L32),""),2) -> #VALUE! | N32: =IF('Dash Board'!$C$17="Error Pls Fill in the Details",0,IFERROR((G32*M32),"")) -> 0 | O32: =IFERROR(VLOOKUP(B32,'Product Master'!$A:$J,7,FALSE),"")
A33: 9 | C33: =IFERROR(VLOOKUP(B33,'Product Master'!$A:$J,2,FALSE),"") | D33: =IFERROR(VLOOKUP(B33,'Product Master'!$A:$J,3,FALSE),"") | E33: =IFERROR(VLOOKUP(B33,'Product Master'!$A:$J,6,FALSE),"") | F33: =IFERROR(VLOOKUP(B33,'Product Master'!$A:$J,4,FALSE),"") | H33: =IFERROR(VLOOKUP(B33,'Product Master'!$A:$J,8,FALSE),"") | I33: =IFERROR(VLOOKUP(B33,'Product Master'!$A:$J,5,FALSE),"") | K33: =IF(ISBLANK($J33),"",$C$17) | L33: =IFERROR(J33+(100%-J33)*K33,"") | M33: =ROUNDUP(IFERROR(I33-(I33*L33),""),2) -> #VALUE! | N33: =IF('Dash Board'!$C$17="Error Pls Fill in the Details",0,IFERROR((G33*M33),"")) -> 0 | O33: =IFERROR(VLOOKUP(B33,'Product Master'!$A:$J,7,FALSE),"")
A34: 10 | C34: =IFERROR(VLOOKUP(B34,'Product Master'!$A:$J,2,FALSE),"") | D34: =IFERROR(VLOOKUP(B34,'Product Master'!$A:$J,3,FALSE),"") | E34: =IFERROR(VLOOKUP(B34,'Product Master'!$A:$J,6,FALSE),"") | F34: =IFERROR(VLOOKUP(B34,'Product Master'!$A:$J,4,FALSE),"") | H34: =IFERROR(VLOOKUP(B34,'Product Master'!$A:$J,8,FALSE),"") | I34: =IFERROR(VLOOKUP(B34,'Product Master'!$A:$J,5,FALSE),"") | K34: =IF(ISBLANK($J34),"",$C$17) | L34: =IFERROR(J34+(100%-J34)*K34,"") | M34: =ROUNDUP(IFERROR(I34-(I34*L34),""),2) -> #VALUE! | N34: =IF('Dash Board'!$C$17="Error Pls Fill in the Details",0,IFERROR((G34*M34),"")) -> 0 | O34: =IFERROR(VLOOKUP(B34,'Product Master'!$A:$J,7,FALSE),"")
A35: 11 | C35: =IFERROR(VLOOKUP(B35,'Product Master'!$A:$J,2,FALSE),"") | D35: =IFERROR(VLOOKUP(B35,'Product Master'!$A:$J,3,FALSE),"") | E35: =IFERROR(VLOOKUP(B35,'Product Master'!$A:$J,6,FALSE),"") | F35: =IFERROR(VLOOKUP(B35,'Product Master'!$A:$J,4,FALSE),"") | H35: =IFERROR(VLOOKUP(B35,'Product Master'!$A:$J,8,FALSE),"") | I35: =IFERROR(VLOOKUP(B35,'Product Master'!$A:$J,5,FALSE),"") | K35: =IF(ISBLANK($J35),"",$C$17) | L35: =IFERROR(J35+(100%-J35)*K35,"") | M35: =ROUNDUP(IFERROR(I35-(I35*L35),""),2) -> #VALUE! | N35: =IF('Dash Board'!$C$17="Error Pls Fill in the Details",0,IFERROR((G35*M35),"")) -> 0 | O35: =IFERROR(VLOOKUP(B35,'Product Master'!$A:$J,7,FALSE),"")
A36: 12 | C36: =IFERROR(VLOOKUP(B36,'Product Master'!$A:$J,2,FALSE),"") | D36: =IFERROR(VLOOKUP(B36,'Product Master'!$A:$J,3,FALSE),"") | E36: =IFERROR(VLOOKUP(B36,'Product Master'!$A:$J,6,FALSE),"") | F36: =IFERROR(VLOOKUP(B36,'Product Master'!$A:$J,4,FALSE),"") | H36: =IFERROR(VLOOKUP(B36,'Product Master'!$A:$J,8,FALSE),"") | I36: =IFERROR(VLOOKUP(B36,'Product Master'!$A:$J,5,FALSE),"") | K36: =IF(ISBLANK($J36),"",$C$17) | L36: =IFERROR(J36+(100%-J36)*K36,"") | M36: =ROUNDUP(IFERROR(I36-(I36*L36),""),2) -> #VALUE! | N36: =IF('Dash Board'!$C$17="Error Pls Fill in the Details",0,IFERROR((G36*M36),"")) -> 0 | O36: =IFERROR(VLOOKUP(B36,'Product Master'!$A:$J,7,FALSE),"")
A37: 13 | C37: =IFERROR(VLOOKUP(B37,'Product Master'!$A:$J,2,FALSE),"") | D37: =IFERROR(VLOOKUP(B37,'Product Master'!$A:$J,3,FALSE),"") | E37: =IFERROR(VLOOKUP(B37,'Product Master'!$A:$J,6,FALSE),"") | F37: =IFERROR(VLOOKUP(B37,'Product Master'!$A:$J,4,FALSE),"") | H37: =IFERROR(VLOOKUP(B37,'Product Master'!$A:$J,8,FALSE),"") | I37: =IFERROR(VLOOKUP(B37,'Product Master'!$A:$J,5,FALSE),"") | K37: =IF(ISBLANK($J37),"",$C$17) | L37: =IFERROR(J37+(100%-J37)*K37,"") | M37: =ROUNDUP(IFERROR(I37-(I37*L37),""),2) -> #VALUE! | N37: =IF('Dash Board'!$C$17="Error Pls Fill in the Details",0,IFERROR((G37*M37),"")) -> 0 | O37: =IFERROR(VLOOKUP(B37,'Product Master'!$A:$J,7,FALSE),"")
... A99: 75 | C99: =IFERROR(VLOOKUP(B99,'Product Master'!$A:$J,2,FALSE),"") | D99: =IFERROR(VLOOKUP(B99,'Product Master'!$A:$J,3,FALSE),"") | E99: =IFERROR(VLOOKUP(B99,'Product Master'!$A:$J,6,FALSE),"") | F99: =IFERROR(VLOOKUP(B99,'Product Master'!$A:$J,4,FALSE),"") | H99: =IFERROR(VLOOKUP(B99,'Product Master'!$A:$J,8,FALSE),"") | I99: =IFERROR(VLOOKUP(B99,'Product Master'!$A:$J,5,FALSE),"") | K99: =IF(ISBLANK($J99),"",$C$17) | L99: =IFERROR(J99+(100%-J99)*K99,"") | M99: =ROUNDUP(IFERROR(I99-(I99*L99),""),2) -> #VALUE! | N99: =IF('Dash Board'!$C$17="Error Pls Fill in the Details",0,IFERROR((G99*M99),"")) -> 0 | O99: =IFERROR(VLOOKUP(B99,'Product Master'!$A:$J,7,FALSE),"")
G100: Basic Order Value (INR) | N100: =SUM(N25:N99) -> 0
G101: GST Amount (INR) | N101: =N100*18% -> 0
G102: Total Order Value (INR) | N102: =N101+N100 -> 0

Sheet Data Validations
A1: Sales Person | B1: Payment Terms | C1: Region | D1: Project Type | E1: Customer Type | F1: Freight Terms | G1: Zonal Manager | H1: Project /Retail | I1: CD % | J1: Date | K1: Order Validity | L1: RERA | M1: 0
A2: International Shipments | B2: Advance | C2: International Sales | D2: Individual Villa -IV | E2: Developer | F2: FOR | G2: S. Mukherjee | H2: Project | I2: 0 | J2: 45292 | K2: 7 Days | L2: Bunglow | M2: 0.01
A3: Huliot Plant 714 & 715 | B3: Under Udaan-Channel Finance | C3: Direct Sales | D3: Housing-Residential Project - HR | E3: Builder | F3: Ex Works | G3: Rahul Adhikari | H3: Retail | I3: 0.03 | J3: 49674 | K3: 10 Days | L3: Hospital | M3: 0.02
A4: Tushar Nag | B4: 30 Days PDC | C4: North East | D4: Commercial Building - CB | E4: Contractor | F4: FOB (Only for Exports) | G4: Amit Deshmukh | K4: 15 Days | L4: Hotel | M4: 0.03
A5: Mriganco Maiti | B5: LC at Sight | C5: Central Zone | D5: Hotel Project - HP | E5: MEP Consultant | F5: CIF (Only for Exports) | L5: Government Project | M5: 0.04
A6: Sumit Sharma | B6: LC 30 Days | C6: North Zone | D6: Hospital & Healthcare - HH | E6: Contractor | M6: 0.05
A7: Yuvraj Rathod | C7: South Zone | D7: Industrial /Government Project - IG | E7: Distributor | M7: 0.06
A8: Pratik Kular | C8: West Zone | D8: Marine - M | M8: 0.07
A9: Himanshu Todi | C9: Retail-Pune | D9: Others | M9: 0.08
A10: Mohit Gupta | C10: Retail-South | M10: 0.09
A11: Yogesh Kumawat | C11: Retail-Maharashtra | M11: 0.1
A12: Vishal Ganwani | M12: 0.11
A13: Vikas Gupta | M13: 0.12
A14: Vivek Vandhu | M14: 0.13
A15: Devsh Arjariya | M15: 0.14
A16: Ganesh Bhosale | M16: 0.15
A17: Aditya Raj | M17: 0.16
A18: Lalit Panwar | M18: 0.17
A19: Surender Banwala | M19: 0.18
A20: Jayaraman Iyer | M20: 0.19
A21: Babu Gs | M21: 0.2
A22: Gokula Kannan | M22: 0.21
A23: Satish Kumar | M23: 0.22
... A44: Vivek Vandhu | M44: 0.43
M45: 0.44
M46: 0.45
M47: 0.46
M48: 0.47
M49: 0.48
M50: 0.49
M51: 0.5
M52: 0.51
M53: 0.52
M54: 0.53
M55: 0.54
M56: 0.55
... M77: 0.76

Sheet Product Master
A1: Item Code | B1: Material Description | C1: DN | D1: MOQ | E1: List Price | F1: Category | G1: Product Sub-Group | H1: HSN Code | I1: GST rate | J1: Category
A2: 54040300-i | B2: HT PRO PIPE WITH ONE SOCKET L 3000 | C2: 40 | D2: 1 | E2: 567 | F2: HT PRO S/S PIPE 3 Mtr | G2: HTPRO S/S PIPE | H2: 39171020 | I2: 0.18 | J2: Mfd Pipes India-HT
A3: 54050300-i | B3: HT PRO PIPE WITH ONE SOCKET L 3000 | C3: 50 | D3: 1 | E3: 740 | F3: HT PRO S/S PIPE 3 Mtr | G3: HTPRO S/S PIPE | H3: 39171020 | I3: 0.18 | J3: Mfd Pipes India-HT
A4: 54075300-i | B4: HT PRO PIPE WITH ONE SOCKET L 3000 | C4: 75 | D4: 1 | E4: 1304 | F4: HT PRO S/S PIPE 3 Mtr | G4: HTPRO S/S PIPE | H4: 39171020 | I4: 0.18 | J4: Mfd Pipes India-HT
A5: 540110300-i | B5: HT PRO PIPE WITH ONE SOCKET L 3000 | C5: 110 | D5: 1 | E5: 1752 | F5: HT PRO S/S PIPE 3 Mtr | G5: HTPRO S/S PIPE | H5: 39171020 | I5: 0.18 | J5: Mfd Pipes India-HT
A6: 540125300-i | B6: HT PRO PIPE WITH ONE SOCKET L 3000 | C6: 125 | D6: 1 | E6: 3401 | F6: HT PRO S/S PIPE 3 Mtr | G6: HTPRO S/S PIPE | H6: 39171020 | I6: 0.18 | J6: Mfd Pipes India-HT
A7: 540160300-i | B7: HT PRO PIPE WITH ONE SOCKET L 3000 | C7: 160 | D7: 1 | E7: 4117 | F7: HT PRO S/S PIPE 3 Mtr | G7: HTPRO S/S PIPE | H7: 39171020 | I7: 0.18 | J7: Mfd Pipes India-HT
A8: 540200300-i | B8: HT PRO PIPE WITH ONE SOCKET L 3000 | C8: 200 | D8: 1 | E8: 8303 | F8: HT PRO S/S PIPE 3 Mtr | G8: HTPRO S/S PIPE | H8: 39171020 | I8: 0.18 | J8: Mfd Pipes India-HT
A9: 5404040300-i | B9: HT PRO PIPE WITH TWO SOCKET L 3000 | C9: 40 | D9: 1 | E9: 588 | F9: HT PRO D/S PIPE 3 Mtr | G9: HTPRO D/S PIPE | H9: 39171020 | I9: 0.18 | J9: Mfd Pipes India-HT
A10: 5405050300-i | B10: HT PRO PIPE WITH TWO SOCKET L 3000 | C10: 50 | D10: 1 | E10: 768 | F10: HT PRO D/S PIPE 3 Mtr | G10: HTPRO D/S PIPE | H10: 39171020 | I10: 0.18 | J10: Mfd Pipes India-HT
A11: 5407575300-i | B11: HT PRO PIPE WITH TWO SOCKET L 3000 | C11: 75 | D11: 1 | E11: 1344 | F11: HT PRO D/S PIPE 3 Mtr | G11: HTPRO D/S PIPE | H11: 39171020 | I11: 0.18 | J11: Mfd Pipes India-HT
A12: 5401111300-i | B12: HT PRO PIPE WITH TWO SOCKET L 3000 | C12: 110 | D12: 1 | E12: 2063 | F12: HT PRO D/S PIPE 3 Mtr | G12: HTPRO D/S PIPE | H12: 39171020 | I12: 0.18 | J12: Mfd Pipes India-HT
A13: 5401212300-i | B13: HT PRO PIPE WITH TWO SOCKET L 3000 | C13: 125 | D13: 1 | E13: 3519 | F13: HT PRO D/S PIPE 3 Mtr | G13: HTPRO D/S PIPE | H13: 39171020 | I13: 0.18 | J13: Mfd Pipes India-HT
... A68: 5401616200-i | B68: HT PRO PIPE WITH TWO SOCKET L 2000 | C68: 160 | D68: 1 | E68: 2947 | F68: HT PRO D/S PIPE 6.0 Ft. | G68: HTPRO D/S PIPE | H68: 39171020 | I68: 0.18 | J68: Mfd Pipes India-HT
A69: 40040150 | B69: HT PRO BEND 15 DEG | C69: 110 | D69: 20 | E69: 234 | F69: HT PRO BEND 15 | G69: HTPRO FITTINGS | H69: 39174000 | I69: 0.18 | J69: Fittings-HT
A70: 40040350 | B70: HT PRO BEND 30 DEG | C70: 110 | D70: 20 | E70: 239 | F70: HT PRO BEND 30 | G70: HTPRO FITTINGS | H70: 39174000 | I70: 0.18 | J70: Fittings-HT
A71: 40010460-i | B71: HT PRO BEND 45 DEG | C71: 40 | D71: 20 | E71: 66 | F71: HT PRO BEND 45 | G71: HTPRO FITTINGS | H71: 39174000 | I71: 0.18 | J71: Fittings-HT
A72: 40020460-i | B72: HT PRO BEND 45 DEG | C72: 50 | D72: 80 | E72: 82 | F72: HT PRO BEND 45 | G72: HTPRO FITTINGS | H72: 39174000 | I72: 0.18 | J72: Fittings-HT
A73: 40030460-i | B73: HT PRO BEND 45 DEG | C73: 75 | D73: 55 | E73: 129 | F73: HT PRO BEND 45 | G73: HTPRO FITTINGS | H73: 39174000 | I73: 0.18 | J73: Fittings-HT
A74: 40040460-i | B74: HT PRO BEND 45 DEG | C74: 110 | D74: 28 | E74: 186 | F74: HT PRO BEND 45 | G74: HTPRO FITTINGS | H74: 39174000 | I74: 0.18 | J74: Fittings-HT
A75: 40050460 | B75: HT PRO BEND 45 DEG | C75: 125 | D75: 10 | E75: 768 | F75: HT PRO BEND 45 | G75: HTPRO FITTINGS | H75: 39174000 | I75: 0.18 | J75: Fittings-HT
A76: 40060460 | B76: HT PRO BEND 45 DEG | C76: 160 | D76: 10 | E76: 1013 | F76: HT PRO BEND 45 | G76: HTPRO FITTINGS | H76: 39174000 | I76: 0.18 | J76: Fittings-HT
A77: 40020467 | B77: HT PRO DOOR BEND 45 DEG | C77: 50 | D77: 60 | E77: 149 | F77: HT PRO DOOR BEND 45 | G77: HTPRO FITTINGS | H77: 39174000 | I77: 0.18 | J77: Fittings-HT
A78: 40040467 | B78: HT PRO DOOR BEND 45 DEG | C78: 110 | D78: 18 | E78: 456 | F78: HT PRO DOOR BEND 45 | G78: HTPRO FITTINGS | H78: 39174000 | I78: 0.18 | J78: Fittings-HT
A79: 40040468 | B79: HT PRO DOOR BEND 45 DEG (RIGHT) | C79: 110 | D79: 18 | E79: 387 | F79: HT PRO DOOR BEND 45 (R) | G79: HTPRO FITTINGS | H79: 39174000 | I79: 0.18 | J79: Fittings-HT
A80: 40040469 | B80: HT PRO DOOR BEND 45 DEG (LEFT) | C80: 110 | D80: 18 | E80: 382 | F80: HT PRO DOOR BEND 45 (L) | G80: HTPRO FITTINGS | H80: 39174000 | I80: 0.18 | J80: Fittings-HT
A81: 40060457 | B81: HT PRO DOOR BEND 45 DEG | C81: 160 | D81: 4 | E81: 1751 | F81: HT PRO DOOR BEND 45 | G81: HTPRO FITTINGS | H81: 39174000 | I81: 0.18 | J81: Fittings-HT
A82: 40060458 | B82: HT PRO DOOR BEND 45 DEG (RIGHT) | C82: 160 | D82: 4 | E82: 1504 | F82: HT PRO DOOR BEND 45 (R) | G82: HTPRO FITTINGS | H82: 39174000 | I82: 0.18 | J82: Fittings-HT
A83: 40060459 | B83: HT PRO DOOR BEND 45 DEG (LEFT) | C83: 160 | D83: 4 | E83: 1626 | F83: HT PRO DOOR BEND 45 (L) | G83: HTPRO FITTINGS | H83: 39174000 | I83: 0.18 | J83: Fittings-HT
A84: 40010860-i | B84: HT PRO BEND 87.5 DEG | C84: 40 | D84: 20 | E84: 72 | F84: HT PRO BEND 87.5 | G84: HTPRO FITTINGS | H84: 39174000 | I84: 0.18 | J84: Fittings-HT
A85: 40020860-i | B85: HT PRO BEND 87.5 DEG | C85: 50 | D85: 70 | E85: 77 | F85: HT PRO BEND 87.5 | G85: HTPRO FITTINGS | H85: 39174000 | I85: 0.18 | J85: Fittings-HT
A86: 40030860 | B86: HT PRO BEND 87.5 DEG | C86: 75 | D86: 20 | E86: 155 | F86: HT PRO BEND 87.5 | G86: HTPRO FITTINGS | H86: 39174000 | I86: 0.18 | J86: Fittings-HT
A87: 40040860-i | B87: HT PRO BEND 87.5 DEG | C87: 110 | D87: 20 | E87: 270 | F87: HT PRO BEND 87.5 | G87: HTPRO FITTINGS | H87: 39174000 | I87: 0.18 | J87: Fittings-HT
A88: 40050860 | B88: HT PRO BEND 87.5 DEG | C88: 125 | D88: 15 | E88: 700 | F88: HT PRO BEND 87.5 | G88: HTPRO FITTINGS | H88: 39174000 | I88: 0.18 | J88: Fittings-HT
A89: 40060860 | B89: HT PRO BEND 87.5 DEG | C89: 160 | D89: 10 | E89: 723 | F89: HT PRO BEND 87.5 | G89: HTPRO FITTINGS | H89: 39174000 | I89: 0.18 | J89: Fittings-HT
A90: 40020867-i | B90: HT PRO DOOR BEND 87.5 DEG | C90: 50 | D90: 60 | E90: 221 | F90: HT PRO DOOR BEND 87.5 | G90: HTPRO FITTINGS | H90: 39174000 | I90: 0.18 | J90: Fittings-HT
A91: 40030867 | B91: HT PRO DOOR BEND 87.5 DEG | C91: 75 | D91: 40 | E91: 209 | F91: HT PRO DOOR BEND 87.5 | G91: HTPRO FITTINGS | H91: 39174000 | I91: 0.18 | J91: Fittings-HT
A92: 40040867-i | B92: HT PRO DOOR BEND 87.5 DEG | C92: 110 | D92: 18 | E92: 518 | F92: HT PRO DOOR BEND 87.5 | G92: HTPRO FITTINGS | H92: 39174000 | I92: 0.18 | J92: Fittings-HT
A93: 40060857 | B93: HT PRO DOOR BEND 87.5 DEG | C93: 160 | D93: 8 | E93: 2429 | F93: HT PRO DOOR BEND 87.5 | G93: HTPRO FITTINGS | H93: 39174000 | I93: 0.18 | J93: Fittings-HT
A94: 40040868-i | B94: HT PRO DOOR BEND 87.5 DEG (RIGHT) | C94: 110 | D94: 18 | E94: 554 | F94: HT PRO DOOR BEND 87.5 (R) | G94: HTPRO FITTINGS | H94: 39174000 | I94: 0.18 | J94: Fittings-HT
...
